Workbook
Name Slicer_Category: #N/A
Name Slicer_Channel: #N/A
Name Slicer_City: #N/A
Name Slicer_Order_Year: #N/A

Sheet README
A1: Field | B1: Details
A2: Project | B2: Retail Sales Analysis — Excel
A3: Dataset size | B3: 1205
A4: Objective | B4: Clean retail sales data and build KPI/Pivot analysis.
A5: Intentional data issues | B5: 5 duplicate rows; some blank/lowercase City values; trailing spaces in Category.
A6: Suggested analysis | B6: Revenue, profit, margin, category/city trends, returns, monthly trend, top products.
A7: Portfolio disclosure | B7: This project uses synthetic data created for learning and portfolio purposes.
A8: Tip | B8: Keep the RAW data unchanged. Clean/analyze in a separate sheet, SQL table, Power Query, or Python notebook.

Sheet Retail_Raw
A1: Order_ID | B1: Order_Date | C1: Customer_ID | D1: City | E1: Category | F1: Product | G1: Quantity | H1: Unit_Price | I1: Discount_Pct | J1: Sales | K1: Cost | L1: Profit | M1: Channel | N1: Payment_Mode | O1: Returned
A2: R00001 | B2: 45690 | C2: C0474 | D2: Jaipur | E2: Fashion | F2: T-Shirt | G2: 2 | H2: 5217.86 | I2: 0.1 | J2: 9392.15 | K2: 7880.02 | L2: 1512.13 | M2: Online | N2: Cash | O2: Yes
A3: R00002 | B3: 45835 | C3: C0214 | D3: Kolkata | E3: Electronics | F3: Headphones | G3: 2 | H3: 5082.03 | I3: 0.15 | J3: 8639.45 | K3: 4816.51 | L3: 3822.94 | M3: Online | N3: Card | O3: No
A4: R00003 | B4: 46014 | C4: C0519 | D4: Delhi | E4: Home | F4: Bottle | G4: 6 | H4: 2053.18 | I4: 0.1 | J4: 11087.17 | K4: 6103.16 | L4: 4984.01 | M4: Online | N4: Card | O4: No
A5: R00004 | B5: 46028 | C5: C0332 | D5: Hyderabad | E5: Electronics | F5: Power Bank | G5: 4 | H5: 4983.19 | I5: 0.2 | J5: 15946.21 | K5: 12246.04 | L5: 3700.17 | M5: Online | N5: Card | O5: No
A6: R00005 | B6: 46207 | C6: C0017 | D6: Noida | E6: Electronics | F6: Power Bank | G6: 5 | H6: 2051.83 | I6: 0.2 | J6: 8207.32 | K6: 6877.01 | L6: 1330.31 | M6: Store | N6: Card | O6: No
A7: R00006 | B7: 45757 | C7: C0164 | D7: Pune | E7: Beauty | F7: Face Wash | G7: 5 | H7: 4206.56 | I7: 0 | J7: 21032.8 | K7: 16501.65 | L7: 4531.15 | M7: Store | N7: UPI | O7: No
A8: R00007 | B8: 45922 | C8: C0021 | D8: Mumbai | E8: Fashion | F8: Shoes | G8: 6 | H8: 1565.16 | I8: 0 | J8: 9390.96 | K8: 7467.25 | L8: 1923.71 | M8: Store | N8: UPI | O8: No
A9: R00008 | B9: 45803 | C9: C0493 | D9: Noida | E9: Home | F9: Lamp | G9: 5 | H9: 789.07 | I9: 0.1 | J9: 3550.82 | K9: 2348.82 | L9: 1202 | M9: Store | N9: Wallet | O9: Yes
A10: R00009 | B10: 45962 | C10: C0247 | D10: Bengaluru | E10: Beauty | F10: Face Wash | G10: 4 | H10: 5105.62 | I10: 0.1 | J10: 18380.23 | K10: 11088.51 | L10: 7291.72 | M10: Online | N10: UPI | O10: No
A11: R00010 | B11: 45676 | C11: C0491 | D11: Pune | E11: Fashion | F11: T-Shirt | G11: 1 | H11: 2653.55 | I11: 0.1 | J11: 2388.2 | K11: 1761.27 | L11: 626.93 | M11: Online | N11: Wallet | O11: Yes
A12: R00011 | B12: 45815 | C12: C0392 | D12: Noida | E12: Home | F12: Lamp | G12: 6 | H12: 4187.53 | I12: 0.05 | J12: 23868.92 | K12: 20074.74 | L12: 3794.18 | M12: Online | N12: Wallet | O12: No
A13: R00012 | B13: 45810 | C13: C0232 | D13: Noida | E13: Beauty | F13: Sunscreen | G13: 3 | H13: 4164.28 | I13: 0 | J13: 12492.84 | K13: 10464.94 | L13: 2027.9 | M13: Store | N13: Wallet | O13: No
... A411: R00410 | B411: 46209 | C411: C0316 | D411: Noida | E411: Home | F411: Lamp | G411: 6 | H411: 4695.74 | I411: 0.05 | J411: 26765.72 | K411: 20563.25 | L411: 6202.47 | M411: Online | N411: Card | O411: No
A412: R00411 | B412: 46083 | C412: C0231 | E412: Electronics | F412: Power Bank | G412: 1 | H412: 2506.2 | I412: 0.2 | J412: 2004.96 | K412: 1384.42 | L412: 620.54 | M412: Online | N412: Wallet | O412: No
A413: R00412 | B413: 46082 | C413: C0020 | D413: Hyderabad | E413: Fashion | F413: Backpack | G413: 3 | H413: 745.83 | I413: 0.05 | J413: 2125.62 | K413: 1243.98 | L413: 881.64 | M413: Store | N413: Wallet | O413: No
A414: R00413 | B414: 45669 | C414: C0494 | D414: Noida | E414: Fashion | F414: Jacket | G414: 4 | H414: 2363.22 | I414: 0.05 | J414: 8980.24 | K414: 6657.85 | L414: 2322.39 | M414: Store | N414: Cash | O414: No
A415: R00414 | B415: 45819 | C415: C0030 | D415: Delhi | E415: Home | F415: Bottle | G415: 6 | H415: 4252.4 | I415: 0 | J415: 25514.4 | K415: 20787.61 | L415: 4726.79 | M415: Store | N415: Card | O415: No
A416: R00415 | B416: 46087 | C416: C0330 | D416: Kolkata | E416: Beauty | F416: Perfume | G416: 6 | H416: 1795.81 | I416: 0 | J416: 10774.86 | K416: 5974.88 | L416: 4799.98 | M416: Online | N416: Card | O416: No
A417: R00416 | B417: 45843 | C417: C0248 | D417: Chennai | E417: Beauty | F417: Perfume | G417: 3 | H417: 5487.44 | I417: 0.15 | J417: 13992.97 | K417: 8709.8 | L417: 5283.17 | M417: Store | N417: Card | O417: No
A418: R00417 | B418: 45979 | C418: C0016 | D418: Noida | E418: Electronics | F418: Power Bank | G418: 4 | H418: 1784.88 | I418: 0.05 | J418: 6782.54 | K418: 4425.52 | L418: 2357.02 | M418: Online | N418: Wallet | O418: Yes
A419: R00418 | B419: 46138 | C419: C0104 | D419: Hyderabad | E419: Beauty | F419: Sunscreen | G419: 5 | H419: 1385.96 | I419: 0 | J419: 6929.8 | K419: 4860.97 | L419: 2068.83 | M419: Store | N419: UPI | O419: No
A420: R00419 | B420: 46154 | C420: C0425 | D420: Kolkata | E420: Fashion | F420: Shoes | G420: 1 | H420: 751.9 | I420: 0.15 | J420: 639.12 | K420: 422.85 | L420: 216.27 | M420: Online | N420: Cash | O420: No
A421: R00420 | B421: 45774 | C421: C0194 | D421: Gurugram | E421: Beauty | F421: Serum | G421: 5 | H421: 3632.24 | I421: 0 | J421: 18161.2 | K421: 12645.08 | L421: 5516.12 | M421: Online | N421: Cash | O421: No
A422: R00421 | B422: 46088 | C422: C0468 | D422: Noida | E422: Home | F422: Mixer | G422: 4 | H422: 1414.64 | I422: 0.1 | J422: 5092.7 | K422: 4168.44 | L422: 924.26 | M422: Store | N422: UPI | O422: No
A423: R00422 | B423: 45697 | C423: C0476 | D423: Delhi | E423: Beauty | F423: Face Wash | G423: 5 | H423: 5021.32 | I423: 0 | J423: 25106.6 | K423: 15976.89 | L423: 9129.71 | M423: Online | N423: Card | O423: No
A424: R00423 | B424: 46250 | C424: C0294 | D424: Mumbai | E424: Fashion | F424: Backpack | G424: 1 | H424: 5276.99 | I424: 0.2 | J424: 4221.59 | K424: 2423.65 | L424: 1797.94 | M424: Online | N424: Card | O424: No
A425: R00424 | B425: 45950 | C425: C0148 | E425: Home | F425: Bottle | G425: 2 | H425: 856.02 | I425: 0.15 | J425: 1455.23 | K425: 1065.2 | L425: 390.03 | M425: Online | N425: Card | O425: No
A426: R00425 | B426: 45952 | C426: C0043 | D426: Chennai | E426: Home | F426: Bottle | G426: 6 | H426: 5246.55 | I426: 0 | J426: 31479.3 | K426: 17716.9 | L426: 13762.4 | M426: Online | N426: Wallet | O426: Yes
A427: R00426 | B427: 45758 | C427: C0285 | D427: Mumbai | E427: Beauty | F427: Face Wash | G427: 3 | H427: 3991.91 | I427: 0.2 | J427: 9580.58 | K427: 6095.36 | L427: 3485.22 | M427: Online | N427: UPI | O427: Yes
A428: R00427 | B428: 45845 | C428: C0189 | D428: Delhi | E428: Beauty | F428: Serum | G428: 2 | H428: 3361.48 | I428: 0.15 | J428: 5714.52 | K428: 3250.65 | L428: 2463.87 | M428: Store | N428: UPI | O428: No
A429: R00428 | B429: 45954 | C429: C0261 | D429: Mumbai | E429: Fashion | F429: Jeans | G429: 6 | H429: 3226.75 | I429: 0 | J429: 19360.5 | K429: 10893.1 | L429: 8467.4 | M429: Online | N429: Cash | O429: No
A430: R00429 | B430: 45789 | C430: C0363 | D430: Chennai | E430: Home | F430: Bedsheet | G430: 4 | H430: 513.62 | I430: 0.05 | J430: 1951.76 | K430: 1142.94 | L430: 808.82 | M430: Store | N430: UPI | O430: No
A431: R00430 | B431: 46228 | C431: C0388 | D431: Pune | E431: Electronics | F431: Mouse | G431: 3 | H431: 5438.29 | I431: 0.15 | J431: 13867.64 | K431: 9000.63 | L431: 4867.01 | M431: Online | N431: Wallet | O431: Yes
A432: R00431 | B432: 45684 | C432: C0453 | D432: Kolkata | E432: Home | F432: Bedsheet | G432: 6 | H432: 4547.7 | I432: 0 | J432: 27286.2 | K432: 18622.55 | L432: 8663.65 | M432: Online | N432: Wallet | O432: Yes
A433: R00432 | B433: 45801 | C433: C0118 | D433: Mumbai | E433: Electronics | F433: Mouse | G433: 4 | H433: 583.48 | I433: 0 | J433: 2333.92 | K433: 1538.67 | L433: 795.25 | M433: Online | N433: Card | O433: No
A434: R00433 | B434: 46214 | C434: C0500 | D434: Jaipur | E434: Fashion | F434: Shoes | G434: 6 | H434: 5254.2 | I434: 0 | J434: 31525.2 | K434: 21334.09 | L434: 10191.11 | M434: Online | N434: Card | O434: No
A435: R00434 | B435: 46113 | C435: C0198 | D435: Pune | E435: Home | F435: Mixer | G435: 6 | H435: 3987.95 | I435: 0 | J435: 23927.7 | K435: 15740.47 | L435: 8187.23 | M435: Store | N435: UPI | O435: No
A436: R00435 | B436: 46197 | C436: C0046 | D436: Jaipur | E436: Fashion | F436: Backpack | G436: 3 | H436: 2376.97 | I436: 0.05 | J436: 6774.36 | K436: 5525.11 | L436: 1249.25 | M436: Store | N436: Card | O436: Yes
A437: R00436 | B437: 45914 | C437: C0181 | D437: Pune | E437: Fashion | F437: Jacket | G437: 6 | H437: 4093.7 | I437: 0.05 | J437: 23334.09 | K437: 16340.31 | L437: 6993.78 | M437: Online | N437: Cash | O437: Yes
...

Sheet Clean_Data
A1: Order_ID | B1: Order_Date | C1: Customer_ID | D1: City | E1: Category | F1: Product | G1: Quantity | H1: Unit_Price | I1: Discount_Pct | J1: Sales | K1: Cost | L1: Profit | M1: Channel | N1: Payment_Mode | O1: Returned | P1: Order_Month | Q1: Order_Year | R1: Profit_Margin
A2: R01111 | B2: 46103 | C2: C0163 | D2: Noida | E2: Beauty | F2: Shampoo | G2: 4 | H2: 156.2 | I2: 0.15 | J2: 531.08 | K2: 414.3 | L2: 116.78 | M2: Store | N2: Cash | O2: Yes | P2: =TEXT(B2,"mmm") -> Mar | Q2: =YEAR(B2) -> 2026 | R2: =IFERROR(L2/J2,0) -> 0.21989154
A3: R00571 | B3: 45697 | C3: C0146 | D3: Gurugram | E3: Beauty | F3: Face Wash | G3: 6 | H3: 156.94 | I3: 0.1 | J3: 847.48 | K3: 584.29 | L3: 263.19 | M3: Store | N3: Card | O3: Yes | P3: =TEXT(B3,"mmm") -> Feb | Q3: =YEAR(B3) -> 2025 | R3: =IFERROR(L3/J3,0) -> 0.310556
A4: R00864 | B4: 46210 | C4: C0428 | D4: Delhi | E4: Fashion | F4: T-Shirt | G4: 5 | H4: 157.92 | I4: 0.15 | J4: 671.16 | K4: 561.68 | L4: 109.48 | M4: Online | N4: Wallet | O4: No | P4: =TEXT(B4,"mmm") -> Jul | Q4: =YEAR(B4) -> 2026 | R4: =IFERROR(L4/J4,0) -> 0.16312057
A5: R00532 | B5: 45985 | C5: C0355 | D5: Delhi | E5: Home | F5: Bedsheet | G5: 5 | H5: 165.05 | I5: 0.15 | J5: 701.46 | K5: 590.43 | L5: 111.03 | M5: Online | N5: Cash | O5: Yes | P5: =TEXT(B5,"mmm") -> Nov | Q5: =YEAR(B5) -> 2025 | R5: =IFERROR(L5/J5,0) -> 0.15828415
A6: R00787 | B6: 45727 | C6: C0205 | D6: Kolkata | E6: Electronics | F6: Smartwatch | G6: 6 | H6: 167.23 | I6: 0.05 | J6: 953.21 | K6: 557.44 | L6: 395.77 | M6: Online | N6: Cash | O6: No | P6: =TEXT(B6,"mmm") -> Mar | Q6: =YEAR(B6) -> 2025 | R6: =IFERROR(L6/J6,0) -> 0.41519707
A7: R00222 | B7: 45922 | C7: C0216 | D7: Bengaluru | E7: Electronics | F7: Smartwatch | G7: 2 | H7: 175.25 | I7: 0.15 | J7: 297.93 | K7: 193.54 | L7: 104.39 | M7: Store | N7: Cash | O7: No | P7: =TEXT(B7,"mmm") -> Sep | Q7: =YEAR(B7) -> 2025 | R7: =IFERROR(L7/J7,0) -> 0.35038432
A8: R01134 | B8: 45690 | C8: C0380 | D8: Pune | E8: Home | F8: Bedsheet | G8: 3 | H8: 184.76 | I8: 0 | J8: 554.28 | K8: 450.91 | L8: 103.37 | M8: Online | N8: UPI | O8: No | P8: =TEXT(B8,"mmm") -> Feb | Q8: =YEAR(B8) -> 2025 | R8: =IFERROR(L8/J8,0) -> 0.18649419
A9: R00147 | B9: 46226 | C9: C0339 | D9: Hyderabad | E9: Electronics | F9: Headphones | G9: 2 | H9: 187.29 | I9: 0 | J9: 374.58 | K9: 283.88 | L9: 90.7 | M9: Store | N9: UPI | O9: No | P9: =TEXT(B9,"mmm") -> Jul | Q9: =YEAR(B9) -> 2026 | R9: =IFERROR(L9/J9,0) -> 0.24213786
A10: R00582 | B10: 46144 | C10: C0175 | D10: Delhi | E10: Electronics | F10: Mouse | G10: 3 | H10: 187.54 | I10: 0 | J10: 562.62 | K10: 316.25 | L10: 246.37 | M10: Online | N10: Cash | O10: No | P10: =TEXT(B10,"mmm") -> May | Q10: =YEAR(B10) -> 2026 | R10: =IFERROR(L10/J10,0) -> 0.43789769
A11: R00740 | B11: 46081 | C11: C0128 | D11: Mumbai | E11: Fashion | F11: Jeans | G11: 6 | H11: 199.23 | I11: 0.15 | J11: 1016.07 | K11: 636.88 | L11: 379.19 | M11: Online | N11: Wallet | O11: Yes | P11: =TEXT(B11,"mmm") -> Feb | Q11: =YEAR(B11) -> 2026 | R11: =IFERROR(L11/J11,0) -> 0.37319279
A12: R00063 | B12: 46257 | C12: C0348 | D12: Kolkata | E12: Electronics | F12: Keyboard | G12: 5 | H12: 207.01 | I12: 0 | J12: 1035.05 | K12: 638.48 | L12: 396.57 | M12: Online | N12: Cash | O12: No | P12: =TEXT(B12,"mmm") -> Aug | Q12: =YEAR(B12) -> 2026 | R12: =IFERROR(L12/J12,0) -> 0.38314091
A13: R00818 | B13: 45964 | C13: C0446 | D13: Noida | E13: Beauty | F13: Perfume | G13: 6 | H13: 207.01 | I13: 0 | J13: 1242.06 | K13: 715 | L13: 527.06 | M13: Store | N13: UPI | O13: No | P13: =TEXT(B13,"mmm") -> Nov | Q13: =YEAR(B13) -> 2025 | R13: =IFERROR(L13/J13,0) -> 0.42434343
... A1201: R00416 | B1201: 45843 | C1201: C0248 | D1201: Chennai | E1201: Beauty | F1201: Perfume | G1201: 3 | H1201: 5487.44 | I1201: 0.15 | J1201: 13992.97 | K1201: 8709.8 | L1201: 5283.17 | M1201: Store | N1201: Card | O1201: No | P1201: =TEXT(B1201,"mmm") -> Jul | Q1201: =YEAR(B1201) -> 2025 | R1201: =IFERROR(L1201/J1201,0) -> 0.37755887

Sheet Analysis
A1: KPI | B1: Value | C1: .
A2: Total Sales | B2: =SUM(Clean_Data!J:J) -> 10926608
A3: Total Orders | B3: =COUNTA(Clean_Data!A:A)-1 -> 1200
A4: Average Order Value | B4: =B2/B3 -> 9105.5069
A5: Total Customers | B5: =COUNTA(_xlfn.UNIQUE(Clean_Data!C2:C1201)) -> 478
A6: Total Quantity | B6: =SUM(Clean_Data!G:G) -> 4252
A7: Total Profit | B7: =SUM(Clean_Data!L:L) -> 3275893.4
A8: Profit Margin | B8: =B7/B2 -> 0.2998088
A9: Top Category by Sales | B9: Fashion | C9: 2936782.6
A10: Top Product by Sales | B10: Backpack | C10: ₹705,219.66
A11: Top City by Sales | B11: Mumbai | C11: 1329580.6
A12: Top Category by Profit | B12: Backpack | C12: ₹875,025.58
A13: Top Sales Channel | B13: Online | C13: 5638053.1
A14: Returned Orders | B14: 317
A15: Return Rate | B15: =317/1200 -> 0.26416667
A16: Top Customer by Sales | B16: C0240 | C16: ₹90,247.39
A17: Top Payment Mode | B17: Card | C17: 2830682.4
A18: Top Sales Year | B18: 2025 | C18: 6769664.2
A20: Business Insights & Recommendations
A22: Insight 1 — Fashion is the strongest category
A23: Actual Observation: Fashion generated the highest sales of ₹2,936,782.56 and the highest profit of ₹875,025.58.
A24: Business Meaning: Fashion is the strongest category in both revenue and profitability.
A25: Recommendation: Maintain strong inventory for Fashion products and use targeted promotions on its best-selling items.
A27: Insight 2 — Backpack is the top-selling product
A28: Actual Observation: Backpack generated the highest product sales of ₹705,219.66.
A29: Business Meaning: Backpack is currently the strongest individual product by revenue.
A30: Recommendation: Ensure sufficient stock availability and consider using Backpack in promotional campaigns or product bundles.
A32: Insight 3 — Online channel performs slightly better than Store
A33: Actual Observation: Online sales were ₹5,638,053.06, compared with Store sales of ₹5,288,555.27.
A34: Business Meaning: Online contributes slightly more revenue than physical Store sales.
... A45: Recommendation: Prioritize inventory availability and targeted marketing in Mumbai while studying successful patterns that can be applied to other cities.

Sheet Pivot_Tables
A1: Sales by Category | D1: Sales by Product | G1: Sales by City | J1: Monthly Sales Trend | M1: Profit by Category | P1: Sales by Channel | S1: Returned Orders Analysis | V1: Top Customers by Sales | Y1: Sales by Payment Mode | AB1: Sales by Year
A2: Category | B2: Sum of Sales | D2: Product | E2: Sum of Sales | G2: City | H2: Sum of Sales | J2: Order_Month | K2: Sum of Sales | M2: Category | N2: Sum of Profit | P2: Channel | Q2: Sum of Sales | S2: Returned | T2: Count of Order_ID | V2: Customer_ID | W2: Sum of Sales | Y2: Payment_Mode | Z2: Sum of Sales | AB2: Order_Year | AC2: Sum of Sales
A3: Fashion | B3: 2936782.6 | D3: Backpack | E3: 705219.66 | G3: Mumbai | H3: 1329580.6 | J3: Jan | K3: 1245910.9 | M3: Fashion | N3: 875025.58 | P3: Online | Q3: 5638053.1 | S3: No | T3: 883 | V3: C0240 | W3: 90247.39 | Y3: Card | Z3: 2830682.4 | AB3: 2025 | AC3: 6769664.2
A4: Home | B4: 2743282.3 | D4: Mixer | E4: 656808.32 | G4: Chennai | H4: 1220391.5 | J4: Feb | K4: 1085011 | M4: Electronics | N4: 834892.71 | P4: Store | Q4: 5288555.3 | S4: Yes | T4: 317 | V4: C0430 | W4: 83457.09 | Y4: UPI | Z4: 2779600 | AB4: 2026 | AC4: 4156944.1
A5: Electronics | B5: 2701550.7 | D5: Jacket | E5: 638609.82 | G5: Bengaluru | H5: 1173305.8 | J5: Mar | K5: 1006006.3 | M5: Home | N5: 809342.13 | P5: Grand Total | Q5: 10926608 | S5: Grand Total | T5: 1200 | V5: C0164 | W5: 80973.28 | Y5: Cash | Z5: 2772913.4 | AB5: Grand Total | AC5: 10926608
A6: Beauty | B6: 2544992.7 | D6: Jeans | E6: 630847.47 | G6: Hyderabad | H6: 1172164.8 | J6: Apr | K6: 1186986.6 | M6: Beauty | N6: 756632.95 | V6: C0468 | W6: 80446.41 | Y6: Wallet | Z6: 2543412.5
A7: Grand Total | B7: 10926608 | D7: Power Bank | E7: 599169.71 | G7: Noida | H7: 1147705.2 | J7: May | K7: 1043253.7 | M7: Grand Total | N7: 3275893.4 | V7: C0500 | W7: 74292.35 | Y7: Grand Total | Z7: 10926608
D8: Shampoo | E8: 597672.58 | G8: Pune | H8: 1109660.1 | J8: Jun | K8: 950508.13 | V8: C0277 | W8: 72484.28
D9: Bottle | E9: 592239.68 | G9: Delhi | H9: 1105537.6 | J9: Jul | K9: 1334992.4 | V9: C0332 | W9: 72260.32
D10: Headphones | E10: 587953.34 | G10: Jaipur | H10: 957209.65 | J10: Aug | K10: 923326.75 | V10: C0172 | W10: 71782.99
D11: Cookware | E11: 584478.12 | G11: Kolkata | H11: 859738.53 | J11: Sep | K11: 663415.58 | V11: C0318 | W11: 71367.71
D12: Keyboard | E12: 567153.21 | G12: Gurugram | H12: 800449.42 | J12: Oct | K12: 435920.88 | V12: C0310 | W12: 70489.44
D13: Grand Total | E13: 6160151.9 | G13: Unknown | H13: 50865.14 | J13: Nov | K13: 564496.56 | V13: C0147 | W13: 64828.12
G14: Grand Total | H14: 10926608 | J14: Dec | K14: 486779.57 | V14: C0392 | W14: 62010
J15: Grand Total | K15: 10926608 | V15: C0027 | W15: 61764.12
V16: C0197 | W16: 61309.05
V17: C0070 | W17: 60889.03
V18: C0118 | W18: 60825.25
V19: C0322 | W19: 59951.41
V20: C0261 | W20: 59325.19
V21: C0153 | W21: 57841.77
V22: C0427 | W22: 57520.45
V23: C0336 | W23: 56911.23
V24: C0303 | W24: 53944.85
V25: C0471 | W25: 53490.99
V26: C0325 | W26: 52722.34
V27: C0129 | W27: 52595.09
... V481: Grand Total | W481: 10926608

Sheet Dashboard
A1: Retail Sales Analysis Dashboard
A4: Total Sales | D4: Total Orders | G4: Average Order Value | J4: Total Profit | M4: Profit Margin
A7: =Analysis!B2 -> 10926608 | D7: =Analysis!B3 -> 1200 | G7: =Analysis!B4 -> 9105.5069 | J7: =Analysis!B7 -> 3275893.4 | M7: =Analysis!B8 -> 0.2998088
